Workbook

Sheet Executive Dashboard
B1: Momentuum Blue - Executive Summary
B2: One-page view of Recruitment, Training and Deployment. Every number is a formula; nothing is typed here. | K2: As of: | L2: =Calc!$H$3 -> 46302
B3: ="Recruitment: week ending "&TEXT('Recruitement Dashboard'!L2,"dd-mmm-yyyy")&" | Training: latest week = "&'Dashboard - Training'!B5&" | Deployment: as of "&TEXT(Calc!$H$3,"dd-mmm-yyyy") -> Recruitment: week ending 25-Sep-2026 | Training: latest week = Week 6 | Deployment: as of 07-Oct-2026
B4: RECRUITMENT: Offers accepted (cuml) | D4: RECRUITMENT: Slots needed next week | F4: TRAINING: Overall average, latest week | H4: DEPLOYMENT: FDEs at clients / total | J4: DEPLOYMENT: Monthly revenue (USD) | L4: DEPLOYMENT: On bench
B5: =G16 -> 17 | D5: =G18 -> 60 | F5: ='Dashboard - Training'!D5 -> 0.96 | H5: ='Deployment Dashboard'!H5&" / "&'Deployment Dashboard'!B5 -> 10 / 38 | J5: ='Deployment Dashboard'!B8 -> 144000 | L5: ='Deployment Dashboard'!J5 -> 2
B6: ="In CTO round now: "&G15 -> In CTO round now: 6 | D6: ="Week ending "&TEXT('Recruitement Dashboard'!L2,"dd-mmm") -> Week ending 25-Sep | F6: ='Dashboard - Training'!B5&" · "&'Dashboard - Training'!J5&" active students" -> Week 6 · 20 active students | H6: ="Utilization "&TEXT('Deployment Dashboard'!L5,"0%") -> Utilization 83% | J6: ="Annualised $"&TEXT('Deployment Dashboard'!D8/1000000,"0.00")&"M" -> Annualised $1.73M | L6: ='Deployment Dashboard'!J8&" contracts ending soon" -> 2 contracts ending soon
B8: RECRUITMENT - FDE hiring by role (Cohort 1 + Cohort 2)
B9: Stage | D9: Associate FDE | E9: FDE | F9: Senior FDE | G9: Total | H9: Candidates in pipeline vs offers accepted, by role
B10: In pipeline now (waiting in any round) | D10: =IF(COUNT('Recruitement Dashboard'!J10,'Recruitement Dashboard'!J22,'Recruitement Dashboard'!J23,'Recruitement Dashboard'!J24,'Recruitement Dashboard'!J25,'Recruitement Dashboard'!J26,'Recruitement Dashboard'!J17,'Recruitement Dashboard'!J38,'Recruitement Dashboard'!J50,'Recruitement Dashboard'!J51,'Recruitement Dashboard'!J52,'Recruitement Dashboard'!J53,'Recruitement Dashboard'!J54,'Recruitement Dashboard'!J45)=0,"–",SUM('Recruitement Dashboard'!J10,'Recruitement Dashboard'!J22,'Recruitement Dashboard'!J23,'Recruitement Dashboard'!J24,'Recruitement Dashboard'!J25,'Recruitement Dashboard'!J26,'Recruitement Dashboard'!J17,'Recruitement Dashboard'!J38,'Recruitement Dashboard'!J50,'Recruitement Dashboard'!J51,'Recruitement Dashboard'!J52,'Recruitement Dashboard'!J53,'Recruitement Dashboard'!J54,'Recruitement Dashboard'!J45)) -> 68 | E10: =IF(COUNT('Recruitement Dashboard'!K10,'Recruitement Dashboard'!K22,'Recruitement Dashboard'!K23,'Recruitement Dashboard'!K24,'Recruitement Dashboard'!K25,'Recruitement Dashboard'!K26,'Recruitement Dashboard'!K17,'Recruitement Dashboard'!K38,'Recruitement Dashboard'!K50,'Recruitement Dashboard'!K51,'Recruitement Dashboard'!K52,'Recruitement Dashboard'!K53,'Recruitement Dashboard'!K54,'Recruitement Dashboard'!K45)=0,"–",SUM('Recruitement Dashboard'!K10,'Recruitement Dashboard'!K22,'Recruitement Dashboard'!K23,'Recruitement Dashboard'!K24,'Recruitement Dashboard'!K25,'Recruitement Dashboard'!K26,'Recruitement Dashboard'!K17,'Recruitement Dashboard'!K38,'Recruitement Dashboard'!K50,'Recruitement Dashboard'!K51,'Recruitement Dashboard'!K52,'Recruitement Dashboard'!K53,'Recruitement Dashboard'!K54,'Recruitement Dashboard'!K45)) -> 17 | F10: =IF(COUNT('Recruitement Dashboard'!L10,'Recruitement Dashboard'!L22,'Recruitement Dashboard'!L23,'Recruitement Dashboard'!L24,'Recruitement Dashboard'!L25,'Recruitement Dashboard'!L26,'Recruitement Dashboard'!L17,'Recruitement Dashboard'!L38,'Recruitement Dashboard'!L50,'Recruitement Dashboard'!L51,'Recruitement Dashboard'!L52,'Recruitement Dashboard'!L53,'Recruitement Dashboard'!L54,'Recruitement Dashboard'!L45)=0,"–",SUM('Recruitement Dashboard'!L10,'Recruitement Dashboard'!L22,'Recruitement Dashboard'!L23,'Recruitement Dashboard'!L24,'Recruitement Dashboard'!L25,'Recruitement Dashboard'!L26,'Recruitement Dashboard'!L17,'Recruitement Dashboard'!L38,'Recruitement Dashboard'!L50,'Recruitement Dashboard'!L51,'Recruitement Dashboard'!L52,'Recruitement Dashboard'!L53,'Recruitement Dashboard'!L54,'Recruitement Dashboard'!L45)) -> 7 | G10: =IF(COUNT(D10:F10)=0,"–",SUM(D10:F10)) -> 92
B11: L1 cleared (cuml) | D11: =IF(COUNT('Recruitement Dashboard'!J12,'Recruitement Dashboard'!J40)=0,"–",SUM('Recruitement Dashboard'!J12,'Recruitement Dashboard'!J40)) -> – | E11: =IF(COUNT('Recruitement Dashboard'!K12,'Recruitement Dashboard'!K40)=0,"–",SUM('Recruitement Dashboard'!K12,'Recruitement Dashboard'!K40)) -> – | F11: =IF(COUNT('Recruitement Dashboard'!L12,'Recruitement Dashboard'!L40)=0,"–",SUM('Recruitement Dashboard'!L12,'Recruitement Dashboard'!L40)) -> – | G11: =IF(COUNT(D11:F11)=0,"–",SUM(D11:F11)) -> –
B12: Berribot assessment cleared (cuml) | D12: =IF(COUNT('Recruitement Dashboard'!J13,'Recruitement Dashboard'!J41)=0,"–",SUM('Recruitement Dashboard'!J13,'Recruitement Dashboard'!J41)) -> – | E12: =IF(COUNT('Recruitement Dashboard'!K13,'Recruitement Dashboard'!K41)=0,"–",SUM('Recruitement Dashboard'!K13,'Recruitement Dashboard'!K41)) -> – | F12: =IF(COUNT('Recruitement Dashboard'!L13,'Recruitement Dashboard'!L41)=0,"–",SUM('Recruitement Dashboard'!L13,'Recruitement Dashboard'!L41)) -> – | G12: =IF(COUNT(D12:F12)=0,"–",SUM(D12:F12)) -> –
B13: L2 cleared (cuml) | D13: =IF(COUNT('Recruitement Dashboard'!J14,'Recruitement Dashboard'!J42)=0,"–",SUM('Recruitement Dashboard'!J14,'Recruitement Dashboard'!J42)) -> – | E13: =IF(COUNT('Recruitement Dashboard'!K14,'Recruitement Dashboard'!K42)=0,"–",SUM('Recruitement Dashboard'!K14,'Recruitement Dashboard'!K42)) -> – | F13: =IF(COUNT('Recruitement Dashboard'!L14,'Recruitement Dashboard'!L42)=0,"–",SUM('Recruitement Dashboard'!L14,'Recruitement Dashboard'!L42)) -> – | G13: =IF(COUNT(D13:F13)=0,"–",SUM(D13:F13)) -> –
B14: L3 cleared (cuml) | D14: =IF(COUNT('Recruitement Dashboard'!J15,'Recruitement Dashboard'!J43)=0,"–",SUM('Recruitement Dashboard'!J15,'Recruitement Dashboard'!J43)) -> – | E14: =IF(COUNT('Recruitement Dashboard'!K15,'Recruitement Dashboard'!K43)=0,"–",SUM('Recruitement Dashboard'!K15,'Recruitement Dashboard'!K43)) -> – | F14: =IF(COUNT('Recruitement Dashboard'!L15,'Recruitement Dashboard'!L43)=0,"–",SUM('Recruitement Dashboard'!L15,'Recruitement Dashboard'!L43)) -> – | G14: =IF(COUNT(D14:F14)=0,"–",SUM(D14:F14)) -> –
B15: In CTO round | D15: =IF(COUNT('Recruitement Dashboard'!J26,'Recruitement Dashboard'!J54)=0,"–",SUM('Recruitement Dashboard'!J26,'Recruitement Dashboard'!J54)) -> 4 | E15: =IF(COUNT('Recruitement Dashboard'!K26,'Recruitement Dashboard'!K54)=0,"–",SUM('Recruitement Dashboard'!K26,'Recruitement Dashboard'!K54)) -> 2 | F15: =IF(COUNT('Recruitement Dashboard'!L26,'Recruitement Dashboard'!L54)=0,"–",SUM('Recruitement Dashboard'!L26,'Recruitement Dashboard'!L54)) -> – | G15: =IF(COUNT(D15:F15)=0,"–",SUM(D15:F15)) -> 6
B16: Offers accepted (cuml) | D16: =IF(COUNT('Recruitement Dashboard'!J18,'Recruitement Dashboard'!J46)=0,"–",SUM('Recruitement Dashboard'!J18,'Recruitement Dashboard'!J46)) -> 14 | E16: =IF(COUNT('Recruitement Dashboard'!K18,'Recruitement Dashboard'!K46)=0,"–",SUM('Recruitement Dashboard'!K18,'Recruitement Dashboard'!K46)) -> 3 | F16: =IF(COUNT('Recruitement Dashboard'!L18,'Recruitement Dashboard'!L46)=0,"–",SUM('Recruitement Dashboard'!L18,'Recruitement Dashboard'!L46)) -> – | G16: =IF(COUNT(D16:F16)=0,"–",SUM(D16:F16)) -> 17
B17: Joined till date (cuml) | D17: =IF(COUNT('Recruitement Dashboard'!J19,'Recruitement Dashboard'!J47)=0,"–",SUM('Recruitement Dashboard'!J19,'Recruitement Dashboard'!J47)) -> – | E17: =IF(COUNT('Recruitement Dashboard'!K19,'Recruitement Dashboard'!K47)=0,"–",SUM('Recruitement Dashboard'!K19,'Recruitement Dashboard'!K47)) -> – | F17: =IF(COUNT('Recruitement Dashboard'!L19,'Recruitement Dashboard'!L47)=0,"–",SUM('Recruitement Dashboard'!L19,'Recruitement Dashboard'!L47)) -> – | G17: =IF(COUNT(D17:F17)=0,"–",SUM(D17:F17)) -> –
B18: Slots needed next week | D18: =IF(COUNT('Recruitement Dashboard'!J29,'Recruitement Dashboard'!J57)=0,"–",SUM('Recruitement Dashboard'!J29,'Recruitement Dashboard'!J57)) -> 50 | E18: =IF(COUNT('Recruitement Dashboard'!K29,'Recruitement Dashboard'!K57)=0,"–",SUM('Recruitement Dashboard'!K29,'Recruitement Dashboard'!K57)) -> 10 | F18: =IF(COUNT('Recruitement Dashboard'!L29,'Recruitement Dashboard'!L57)=0,"–",SUM('Recruitement Dashboard'!L29,'Recruitement Dashboard'!L57)) -> – | G18: =IF(COUNT(D18:F18)=0,"–",SUM(D18:F18)) -> 60
B22: TRAINING - Academy weekly scores
B23: ="Overall average · "&'Dashboard - Training'!B5 -> Overall average · Week 6 | E23: Hands-on assignments average | H23: Proctored assessment average | K23: Active students
B24: ='Dashboard - Training'!D5 -> 0.96 | E24: ='Dashboard - Training'!F5 -> 0.95 | H24: ='Dashboard - Training'!H5 -> 0.97 | K24: ='Dashboard - Training'!J5 -> 20
B25: Overall weekly average, Weeks 1-12
B41: DEPLOYMENT - where FDEs are based, when they are available and where they work
B42: ="WHERE FDEs ARE BASED"&CHAR(10)&'Deployment Dashboard'!B5&" FDEs" -> WHERE FDEs ARE BASED 38 FDEs | G42: ="AVAILABILITY"&CHAR(10)&Calc!B99&" now · "&Calc!B100&" later" -> AVAILABILITY 12 now · 26 later | L42: ="DEPLOYMENT"&CHAR(10)&TEXT('Deployment Dashboard'!B8/1000,"$0.0")&"K/mo · "&COUNTIF(Calc!B60:B65,">0")&" clients" -> DEPLOYMENT $144.0K/mo · 6 clients
B43: =IFERROR(INDEX(Calc!$O$91:$O$96,MATCH(ROW()-ROW($B$43),Calc!$N$91:$N$96,0)),"") | L43: =IFERROR(INDEX(Calc!$O$103:$O$111,MATCH(ROW()-ROW($L$43),Calc!$N$103:$N$111,0)),"")
B44: =IFERROR(INDEX(Calc!$O$91:$O$96,MATCH(ROW()-ROW($B$43),Calc!$N$91:$N$96,0)),"") | L44: =IFERROR(INDEX(Calc!$O$103:$O$111,MATCH(ROW()-ROW($L$43),Calc!$N$103:$N$111,0)),"") -> TriNet · 4 · $48.0K/mo
B45: =IFERROR(INDEX(Calc!$O$91:$O$96,MATCH(ROW()-ROW($B$43),Calc!$N$91:$N$96,0)),"") | L45: =IFERROR(INDEX(Calc!$O$103:$O$111,MATCH(ROW()-ROW($L$43),Calc!$N$103:$N$111,0)),"")
B46: =IFERROR(INDEX(Calc!$O$91:$O$96,MATCH(ROW()-ROW($B$43),Calc!$N$91:$N$96,0)),"") | L46: =IFERROR(INDEX(Calc!$O$103:$O$111,MATCH(ROW()-ROW($L$43),Calc!$N$103:$N$111,0)),"")
B47: =IFERROR(INDEX(Calc!$O$91:$O$96,MATCH(ROW()-ROW($B$43),Calc!$N$91:$N$96,0)),"") | L47: =IFERROR(INDEX(Calc!$O$103:$O$111,MATCH(ROW()-ROW($L$43),Calc!$N$103:$N$111,0)),"") -> PMI · 1 · $16.0K/mo
B48: =IFERROR(INDEX(Calc!$O$91:$O$96,MATCH(ROW()-ROW($B$43),Calc!$N$91:$N$96,0)),"") | L48: =IFERROR(INDEX(Calc!$O$103:$O$111,MATCH(ROW()-ROW($L$43),Calc!$N$103:$N$111,0)),"") -> Hiscox · 1 · $16.0K/mo
B49: =IFERROR(INDEX(Calc!$O$91:$O$96,MATCH(ROW()-ROW($B$43),Calc!$N$91:$N$96,0)),"") | L49: =IFERROR(INDEX(Calc!$O$103:$O$111,MATCH(ROW()-ROW($L$43),Calc!$N$103:$N$111,0)),"") -> SEI · 2 · $32.0K/mo
B50: =IFERROR(INDEX(Calc!$O$91:$O$96,MATCH(ROW()-ROW($B$43),Calc!$N$91:$N$96,0)),"") | L50: =IFERROR(INDEX(Calc!$O$103:$O$111,MATCH(ROW()-ROW($L$43),Calc!$N$103:$N$111,0)),"")
B51: =IFERROR(INDEX(Calc!$O$91:$O$96,MATCH(ROW()-ROW($B$43),Calc!$N$91:$N$96,0)),"") | L51: =IFERROR(INDEX(Calc!$O$103:$O$111,MATCH(ROW()-ROW($L$43),Calc!$N$103:$N$111,0)),"") -> M&T Bank · 1 · $16.0K/mo
B52: =IFERROR(INDEX(Calc!$O$91:$O$96,MATCH(ROW()-ROW($B$43),Calc!$N$91:$N$96,0)),"") | L52: =IFERROR(INDEX(Calc!$O$103:$O$111,MATCH(ROW()-ROW($L$43),Calc!$N$103:$N$111,0)),"") -> Peabody · 1 · $16.0K/mo
B53: =IFERROR(INDEX(Calc!$O$91:$O$96,MATCH(ROW()-ROW($B$43),Calc!$N$91:$N$96,0)),"") | L53: =IFERROR(INDEX(Calc!$O$103:$O$111,MATCH(ROW()-ROW($L$43),Calc!$N$103:$N$111,0)),"")
B54: =IFERROR(INDEX(Calc!$O$91:$O$96,MATCH(ROW()-ROW($B$43),Calc!$N$91:$N$96,0)),"") -> USA · 28 | L54: =IFERROR(INDEX(Calc!$O$103:$O$111,MATCH(ROW()-ROW($L$43),Calc!$N$103:$N$111,0)),"") -> Current bench · 2
... B76: =IFERROR(INDEX(Calc!$O$91:$O$96,MATCH(ROW()-ROW($B$43),Calc!$N$91:$N$96,0)),"") | L76: =IFERROR(INDEX(Calc!$O$103:$O$111,MATCH(ROW()-ROW($L$43),Calc!$N$103:$N$111,0)),"")
B78: Notes
B79: Recruitment: each number is the same role column on the Recruitement Dashboard with Cohort 1 and Cohort 2 added together, for the week set in that dashboard's yellow week-ending cell. A '–' means HR has not reported that number. 'In pipeline now' adds every pending count (screening, L1, Berribot, L2, L3, CTO, offer extended).
B80: Training: latest reported week from the Dashboard - Training sheet (data typed on Input - Trainers). The line shows the overall weekly average for weeks 1-12 and fills in as each week is entered.
B81: Deployment: cards read the Deployment Dashboard. The flow chart is drawn from the Calc sheet (rows 74 onwards: location x availability x client), so it redraws whenever Master-Input changes. Box and ribbon heights are to scale across all three columns. (It is two transparent charts stacked exactly on top of each other, because ribbons cross and one chart cannot draw crossing ribbons.)
...

Sheet Recruitement Dashboard
B1: FDE Hiring Pipeline Dashboard - by Cohort and Role
B2: Counts come straight from the HR-Input sheet (weekly). A '–' means that number has not been reported. | J2: Week ending: | L2: =MAX('HR-Input'!$A$2:$A$500) -> 46290
B3: Yellow cell: defaults to the latest week; type an earlier week-ending date to view history.
B4: Cohort 1 recruitment
B5: In pipeline now | D5: In CTO round | F5: Offers accepted (cuml) | H5: Joined (cuml) | J5: Rejected (cuml) | L5: Slots needed next week
B6: =IF(COUNT(M10,M22,M23,M24,M25,M26,M17)=0,"–",SUM(M10,M22,M23,M24,M25,M26,M17)) -> 24 | D6: =M26 -> 2 | F6: =M18 -> 3 | H6: =M19 -> – | J6: =M28 -> 20 | L6: =M29 -> 10
H8: Stage | J8: Associate FDE | K8: FDE | L8: Senior FDE | M8: Total
H9: Recruitment flow, in order (this is what the chart shows)
H10: Screening pending | J10: =IF(COUNTIFS('HR-Input'!$A$2:$A$500,$L$2,'HR-Input'!$B$2:$B$500,"Cohort 1",'HR-Input'!$C$2:$C$500,"Associate FDE",'HR-Input'!$F$2:$F$500,"<>")=0,"–",SUMIFS('HR-Input'!$F$2:$F$500,'HR-Input'!$A$2:$A$500,$L$2,'HR-Input'!$B$2:$B$500,"Cohort 1",'HR-Input'!$C$2:$C$500,"Associate FDE")) -> – | K10: =IF(COUNTIFS('HR-Input'!$A$2:$A$500,$L$2,'HR-Input'!$B$2:$B$500,"Cohort 1",'HR-Input'!$C$2:$C$500,"FDE",'HR-Input'!$F$2:$F$500,"<>")=0,"–",SUMIFS('HR-Input'!$F$2:$F$500,'HR-Input'!$A$2:$A$500,$L$2,'HR-Input'!$B$2:$B$500,"Cohort 1",'HR-Input'!$C$2:$C$500,"FDE")) -> – | L10: =IF(COUNTIFS('HR-Input'!$A$2:$A$500,$L$2,'HR-Input'!$B$2:$B$500,"Cohort 1",'HR-Input'!$C$2:$C$500,"Senior FDE",'HR-Input'!$F$2:$F$500,"<>")=0,"–",SUMIFS('HR-Input'!$F$2:$F$500,'HR-Input'!$A$2:$A$500,$L$2,'HR-Input'!$B$2:$B$500,"Cohort 1",'HR-Input'!$C$2:$C$500,"Senior FDE")) -> 6 | M10: =IF(COUNT(J10:L10)=0,"–",SUM(J10:L10)) -> 6
H11: Screening cleared (cuml) | J11: =IF(COUNTIFS('HR-Input'!$A$2:$A$500,$L$2,'HR-Input'!$B$2:$B$500,"Cohort 1",'HR-Input'!$C$2:$C$500,"Associate FDE",'HR-Input'!$G$2:$G$500,"<>")=0,"–",SUMIFS('HR-Input'!$G$2:$G$500,'HR-Input'!$A$2:$A$500,$L$2,'HR-Input'!$B$2:$B$500,"Cohort 1",'HR-Input'!$C$2:$C$500,"Associate FDE")) -> – | K11: =IF(COUNTIFS('HR-Input'!$A$2:$A$500,$L$2,'HR-Input'!$B$2:$B$500,"Cohort 1",'HR-Input'!$C$2:$C$500,"FDE",'HR-Input'!$G$2:$G$500,"<>")=0,"–",SUMIFS('HR-Input'!$G$2:$G$500,'HR-Input'!$A$2:$A$500,$L$2,'HR-Input'!$B$2:$B$500,"Cohort 1",'HR-Input'!$C$2:$C$500,"FDE")) -> – | L11: =IF(COUNTIFS('HR-Input'!$A$2:$A$500,$L$2,'HR-Input'!$B$2:$B$500,"Cohort 1",'HR-Input'!$C$2:$C$500,"Senior FDE",'HR-Input'!$G$2:$G$500,"<>")=0,"–",SUMIFS('HR-Input'!$G$2:$G$500,'HR-Input'!$A$2:$A$500,$L$2,'HR-Input'!$B$2:$B$500,"Cohort 1",'HR-Input'!$C$2:$C$500,"Senior FDE")) -> – | M11: =IF(COUNT(J11:L11)=0,"–",SUM(J11:L11)) -> –
H12: L1 cleared (cuml) | J12: =IF(COUNTIFS('HR-Input'!$A$2:$A$500,$L$2,'HR-Input'!$B$2:$B$500,"Cohort 1",'HR-Input'!$C$2:$C$500,"Associate FDE",'HR-Input'!$I$2:$I$500,"<>")=0,"–",SUMIFS('HR-Input'!$I$2:$I$500,'HR-Input'!$A$2:$A$500,$L$2,'HR-Input'!$B$2:$B$500,"Cohort 1",'HR-Input'!$C$2:$C$500,"Associate FDE")) -> – | K12: =IF(COUNTIFS('HR-Input'!$A$2:$A$500,$L$2,'HR-Input'!$B$2:$B$500,"Cohort 1",'HR-Input'!$C$2:$C$500,"FDE",'HR-Input'!$I$2:$I$500,"<>")=0,"–",SUMIFS('HR-Input'!$I$2:$I$500,'HR-Input'!$A$2:$A$500,$L$2,'HR-Input'!$B$2:$B$500,"Cohort 1",'HR-Input'!$C$2:$C$500,"FDE")) -> – | L12: =IF(COUNTIFS('HR-Input'!$A$2:$A$500,$L$2,'HR-Input'!$B$2:$B$500,"Cohort 1",'HR-Input'!$C$2:$C$500,"Senior FDE",'HR-Input'!$I$2:$I$500,"<>")=0,"–",SUMIFS('HR-Input'!$I$2:$I$500,'HR-Input'!$A$2:$A$500,$L$2,'HR-Input'!$B$2:$B$500,"Cohort 1",'HR-Input'!$C$2:$C$500,"Senior FDE")) -> – | M12: =IF(COUNT(J12:L12)=0,"–",SUM(J12:L12)) -> –
H13: Berribot assessment cleared (cuml) | J13: =IF(COUNTIFS('HR-Input'!$A$2:$A$500,$L$2,'HR-Input'!$B$2:$B$500,"Cohort 1",'HR-Input'!$C$2:$C$500,"Associate FDE",'HR-Input'!$K$2:$K$500,"<>")=0,"–",SUMIFS('HR-Input'!$K$2:$K$500,'HR-Input'!$A$2:$A$500,$L$2,'HR-Input'!$B$2:$B$500,"Cohort 1",'HR-Input'!$C$2:$C$500,"Associate FDE")) -> – | K13: =IF(COUNTIFS('HR-Input'!$A$2:$A$500,$L$2,'HR-Input'!$B$2:$B$500,"Cohort 1",'HR-Input'!$C$2:$C$500,"FDE",'HR-Input'!$K$2:$K$500,"<>")=0,"–",SUMIFS('HR-Input'!$K$2:$K$500,'HR-Input'!$A$2:$A$500,$L$2,'HR-Input'!$B$2:$B$500,"Cohort 1",'HR-Input'!$C$2:$C$500,"FDE")) -> – | L13: =IF(COUNTIFS('HR-Input'!$A$2:$A$500,$L$2,'HR-Input'!$B$2:$B$500,"Cohort 1",'HR-Input'!$C$2:$C$500,"Senior FDE",'HR-Input'!$K$2:$K$500,"<>")=0,"–",SUMIFS('HR-Input'!$K$2:$K$500,'HR-Input'!$A$2:$A$500,$L$2,'HR-Input'!$B$2:$B$500,"Cohort 1",'HR-Input'!$C$2:$C$500,"Senior FDE")) -> – | M13: =IF(COUNT(J13:L13)=0,"–",SUM(J13:L13)) -> –
H14: L2 cleared (cuml) | J14: =IF(COUNTIFS('HR-Input'!$A$2:$A$500,$L$2,'HR-Input'!$B$2:$B$500,"Cohort 1",'HR-Input'!$C$2:$C$500,"Associate FDE",'HR-Input'!$M$2:$M$500,"<>")=0,"–",SUMIFS('HR-Input'!$M$2:$M$500,'HR-Input'!$A$2:$A$500,$L$2,'HR-Input'!$B$2:$B$500,"Cohort 1",'HR-Input'!$C$2:$C$500,"Associate FDE")) -> – | K14: =IF(COUNTIFS('HR-Input'!$A$2:$A$500,$L$2,'HR-Input'!$B$2:$B$500,"Cohort 1",'HR-Input'!$C$2:$C$500,"FDE",'HR-Input'!$M$2:$M$500,"<>")=0,"–",SUMIFS('HR-Input'!$M$2:$M$500,'HR-Input'!$A$2:$A$500,$L$2,'HR-Input'!$B$2:$B$500,"Cohort 1",'HR-Input'!$C$2:$C$500,"FDE")) -> – | L14: =IF(COUNTIFS('HR-Input'!$A$2:$A$500,$L$2,'HR-Input'!$B$2:$B$500,"Cohort 1",'HR-Input'!$C$2:$C$500,"Senior FDE",'HR-Input'!$M$2:$M$500,"<>")=0,"–",SUMIFS('HR-Input'!$M$2:$M$500,'HR-Input'!$A$2:$A$500,$L$2,'HR-Input'!$B$2:$B$500,"Cohort 1",'HR-Input'!$C$2:$C$500,"Senior FDE")) -> – | M14: =IF(COUNT(J14:L14)=0,"–",SUM(J14:L14)) -> –
H15: L3 cleared (cuml) | J15: =IF(COUNTIFS('HR-Input'!$A$2:$A$500,$L$2,'HR-Input'!$B$2:$B$500,"Cohort 1",'HR-Input'!$C$2:$C$500,"Associate FDE",'HR-Input'!$O$2:$O$500,"<>")=0,"–",SUMIFS('HR-Input'!$O$2:$O$500,'HR-Input'!$A$2:$A$500,$L$2,'HR-Input'!$B$2:$B$500,"Cohort 1",'HR-Input'!$C$2:$C$500,"Associate FDE")) -> – | K15: =IF(COUNTIFS('HR-Input'!$A$2:$A$500,$L$2,'HR-Input'!$B$2:$B$500,"Cohort 1",'HR-Input'!$C$2:$C$500,"FDE",'HR-Input'!$O$2:$O$500,"<>")=0,"–",SUMIFS('HR-Input'!$O$2:$O$500,'HR-Input'!$A$2:$A$500,$L$2,'HR-Input'!$B$2:$B$500,"Cohort 1",'HR-Input'!$C$2:$C$500,"FDE")) -> – | L15: =IF(COUNTIFS('HR-Input'!$A$2:$A$500,$L$2,'HR-Input'!$B$2:$B$500,"Cohort 1",'HR-Input'!$C$2:$C$500,"Senior FDE",'HR-Input'!$O$2:$O$500,"<>")=0,"–",SUMIFS('HR-Input'!$O$2:$O$500,'HR-Input'!$A$2:$A$500,$L$2,'HR-Input'!$B$2:$B$500,"Cohort 1",'HR-Input'!$C$2:$C$500,"Senior FDE")) -> – | M15: =IF(COUNT(J15:L15)=0,"–",SUM(J15:L15)) -> –
H16: CTO round cleared (cuml) | J16: =IF(COUNTIFS('HR-Input'!$A$2:$A$500,$L$2,'HR-Input'!$B$2:$B$500,"Cohort 1",'HR-Input'!$C$2:$C$500,"Associate FDE",'HR-Input'!$Q$2:$Q$500,"<>")=0,"–",SUMIFS('HR-Input'!$Q$2:$Q$500,'HR-Input'!$A$2:$A$500,$L$2,'HR-Input'!$B$2:$B$500,"Cohort 1",'HR-Input'!$C$2:$C$500,"Associate FDE")) -> – | K16: =IF(COUNTIFS('HR-Input'!$A$2:$A$500,$L$2,'HR-Input'!$B$2:$B$500,"Cohort 1",'HR-Input'!$C$2:$C$500,"FDE",'HR-Input'!$Q$2:$Q$500,"<>")=0,"–",SUMIFS('HR-Input'!$Q$2:$Q$500,'HR-Input'!$A$2:$A$500,$L$2,'HR-Input'!$B$2:$B$500,"Cohort 1",'HR-Input'!$C$2:$C$500,"FDE")) -> – | L16: =IF(COUNTIFS('HR-Input'!$A$2:$A$500,$L$2,'HR-Input'!$B$2:$B$500,"Cohort 1",'HR-Input'!$C$2:$C$500,"Senior FDE",'HR-Input'!$Q$2:$Q$500,"<>")=0,"–",SUMIFS('HR-Input'!$Q$2:$Q$500,'HR-Input'!$A$2:$A$500,$L$2,'HR-Input'!$B$2:$B$500,"Cohort 1",'HR-Input'!$C$2:$C$500,"Senior FDE")) -> – | M16: =IF(COUNT(J16:L16)=0,"–",SUM(J16:L16)) -> –
H17: Offer extended (pending) | J17: =IF(COUNTIFS('HR-Input'!$A$2:$A$500,$L$2,'HR-Input'!$B$2:$B$500,"Cohort 1",'HR-Input'!$C$2:$C$500,"Associate FDE",'HR-Input'!$R$2:$R$500,"<>")=0,"–",SUMIFS('HR-Input'!$R$2:$R$500,'HR-Input'!$A$2:$A$500,$L$2,'HR-Input'!$B$2:$B$500,"Cohort 1",'HR-Input'!$C$2:$C$500,"Associate FDE")) -> – | K17: =IF(COUNTIFS('HR-Input'!$A$2:$A$500,$L$2,'HR-Input'!$B$2:$B$500,"Cohort 1",'HR-Input'!$C$2:$C$500,"FDE",'HR-Input'!$R$2:$R$500,"<>")=0,"–",SUMIFS('HR-Input'!$R$2:$R$500,'HR-Input'!$A$2:$A$500,$L$2,'HR-Input'!$B$2:$B$500,"Cohort 1",'HR-Input'!$C$2:$C$500,"FDE")) -> – | L17: =IF(COUNTIFS('HR-Input'!$A$2:$A$500,$L$2,'HR-Input'!$B$2:$B$500,"Cohort 1",'HR-Input'!$C$2:$C$500,"Senior FDE",'HR-Input'!$R$2:$R$500,"<>")=0,"–",SUMIFS('HR-Input'!$R$2:$R$500,'HR-Input'!$A$2:$A$500,$L$2,'HR-Input'!$B$2:$B$500,"Cohort 1",'HR-Input'!$C$2:$C$500,"Senior FDE")) -> – | M17: =IF(COUNT(J17:L17)=0,"–",SUM(J17:L17)) -> –
H18: Offers accepted (cuml) | J18: =IF(COUNTIFS('HR-Input'!$A$2:$A$500,$L$2,'HR-Input'!$B$2:$B$500,"Cohort 1",'HR-Input'!$C$2:$C$500,"Associate FDE",'HR-Input'!$S$2:$S$500,"<>")=0,"–",SUMIFS('HR-Input'!$S$2:$S$500,'HR-Input'!$A$2:$A$500,$L$2,'HR-Input'!$B$2:$B$500,"Cohort 1",'HR-Input'!$C$2:$C$500,"Associate FDE")) -> – | K18: =IF(COUNTIFS('HR-Input'!$A$2:$A$500,$L$2,'HR-Input'!$B$2:$B$500,"Cohort 1",'HR-Input'!$C$2:$C$500,"FDE",'HR-Input'!$S$2:$S$500,"<>")=0,"–",SUMIFS('HR-Input'!$S$2:$S$500,'HR-Input'!$A$2:$A$500,$L$2,'HR-Input'!$B$2:$B$500,"Cohort 1",'HR-Input'!$C$2:$C$500,"FDE")) -> 3 | L18: =IF(COUNTIFS('HR-Input'!$A$2:$A$500,$L$2,'HR-Input'!$B$2:$B$500,"Cohort 1",'HR-Input'!$C$2:$C$500,"Senior FDE",'HR-Input'!$S$2:$S$500,"<>")=0,"–",SUMIFS('HR-Input'!$S$2:$S$500,'HR-Input'!$A$2:$A$500,$L$2,'HR-Input'!$B$2:$B$500,"Cohort 1",'HR-Input'!$C$2:$C$500,"Senior FDE")) -> – | M18: =IF(COUNT(J18:L18)=0,"–",SUM(J18:L18)) -> 3
H19: Joined (cuml) | J19: =IF(COUNTIFS('HR-Input'!$A$2:$A$500,$L$2,'HR-Input'!$B$2:$B$500,"Cohort 1",'HR-Input'!$C$2:$C$500,"Associate FDE",'HR-Input'!$T$2:$T$500,"<>")=0,"–",SUMIFS('HR-Input'!$T$2:$T$500,'HR-Input'!$A$2:$A$500,$L$2,'HR-Input'!$B$2:$B$500,"Cohort 1",'HR-Input'!$C$2:$C$500,"Associate FDE")) -> – | K19: =IF(COUNTIFS('HR-Input'!$A$2:$A$500,$L$2,'HR-Input'!$B$2:$B$500,"Cohort 1",'HR-Input'!$C$2:$C$500,"FDE",'HR-Input'!$T$2:$T$500,"<>")=0,"–",SUMIFS('HR-Input'!$T$2:$T$500,'HR-Input'!$A$2:$A$500,$L$2,'HR-Input'!$B$2:$B$500,"Cohort 1",'HR-Input'!$C$2:$C$500,"FDE")) -> – | L19: =IF(COUNTIFS('HR-Input'!$A$2:$A$500,$L$2,'HR-Input'!$B$2:$B$500,"Cohort 1",'HR-Input'!$C$2:$C$500,"Senior FDE",'HR-Input'!$T$2:$T$500,"<>")=0,"–",SUMIFS('HR-Input'!$T$2:$T$500,'HR-Input'!$A$2:$A$500,$L$2,'HR-Input'!$B$2:$B$500,"Cohort 1",'HR-Input'!$C$2:$C$500,"Senior FDE")) -> – | M19: =IF(COUNT(J19:L19)=0,"–",SUM(J19:L19)) -> –
H20: Other counts
H21: Applications (cuml) | J21: =IF(COUNTIFS('HR-Input'!$A$2:$A$500,$L$2,'HR-Input'!$B$2:$B$500,"Cohort 1",'HR-Input'!$C$2:$C$500,"Associate FDE",'HR-Input'!$E$2:$E$500,"<>")=0,"–",SUMIFS('HR-Input'!$E$2:$E$500,'HR-Input'!$A$2:$A$500,$L$2,'HR-Input'!$B$2:$B$500,"Cohort 1",'HR-Input'!$C$2:$C$500,"Associate FDE")) -> – | K21: =IF(COUNTIFS('HR-Input'!$A$2:$A$500,$L$2,'HR-Input'!$B$2:$B$500,"Cohort 1",'HR-Input'!$C$2:$C$500,"FDE",'HR-Input'!$E$2:$E$500,"<>")=0,"–",SUMIFS('HR-Input'!$E$2:$E$500,'HR-Input'!$A$2:$A$500,$L$2,'HR-Input'!$B$2:$B$500,"Cohort 1",'HR-Input'!$C$2:$C$500,"FDE")) -> – | L21: =IF(COUNTIFS('HR-Input'!$A$2:$A$500,$L$2,'HR-Input'!$B$2:$B$500,"Cohort 1",'HR-Input'!$C$2:$C$500,"Senior FDE",'HR-Input'!$E$2:$E$500,"<>")=0,"–",SUMIFS('HR-Input'!$E$2:$E$500,'HR-Input'!$A$2:$A$500,$L$2,'HR-Input'!$B$2:$B$500,"Cohort 1",'HR-Input'!$C$2:$C$500,"Senior FDE")) -> 16 | M21: =IF(COUNT(J21:L21)=0,"–",SUM(J21:L21)) -> 16
H22: L1 pending | J22: =IF(COUNTIFS('HR-Input'!$A$2:$A$500,$L$2,'HR-Input'!$B$2:$B$500,"Cohort 1",'HR-Input'!$C$2:$C$500,"Associate FDE",'HR-Input'!$H$2:$H$500,"<>")=0,"–",SUMIFS('HR-Input'!$H$2:$H$500,'HR-Input'!$A$2:$A$500,$L$2,'HR-Input'!$B$2:$B$500,"Cohort 1",'HR-Input'!$C$2:$C$500,"Associate FDE")) -> – | K22: =IF(COUNTIFS('HR-Input'!$A$2:$A$500,$L$2,'HR-Input'!$B$2:$B$500,"Cohort 1",'HR-Input'!$C$2:$C$500,"FDE",'HR-Input'!$H$2:$H$500,"<>")=0,"–",SUMIFS('HR-Input'!$H$2:$H$500,'HR-Input'!$A$2:$A$500,$L$2,'HR-Input'!$B$2:$B$500,"Cohort 1",'HR-Input'!$C$2:$C$500,"FDE")) -> – | L22: =IF(COUNTIFS('HR-Input'!$A$2:$A$500,$L$2,'HR-Input'!$B$2:$B$500,"Cohort 1",'HR-Input'!$C$2:$C$500,"Senior FDE",'HR-Input'!$H$2:$H$500,"<>")=0,"–",SUMIFS('HR-Input'!$H$2:$H$500,'HR-Input'!$A$2:$A$500,$L$2,'HR-Input'!$B$2:$B$500,"Cohort 1",'HR-Input'!$C$2:$C$500,"Senior FDE")) -> – | M22: =IF(COUNT(J22:L22)=0,"–",SUM(J22:L22)) -> –
H23: Berribot assessment applied (pending) | J23: =IF(COUNTIFS('HR-Input'!$A$2:$A$500,$L$2,'HR-Input'!$B$2:$B$500,"Cohort 1",'HR-Input'!$C$2:$C$500,"Associate FDE",'HR-Input'!$J$2:$J$500,"<>")=0,"–",SUMIFS('HR-Input'!$J$2:$J$500,'HR-Input'!$A$2:$A$500,$L$2,'HR-Input'!$B$2:$B$500,"Cohort 1",'HR-Input'!$C$2:$C$500,"Associate FDE")) -> – | K23: =IF(COUNTIFS('HR-Input'!$A$2:$A$500,$L$2,'HR-Input'!$B$2:$B$500,"Cohort 1",'HR-Input'!$C$2:$C$500,"FDE",'HR-Input'!$J$2:$J$500,"<>")=0,"–",SUMIFS('HR-Input'!$J$2:$J$500,'HR-Input'!$A$2:$A$500,$L$2,'HR-Input'!$B$2:$B$500,"Cohort 1",'HR-Input'!$C$2:$C$500,"FDE")) -> – | L23: =IF(COUNTIFS('HR-Input'!$A$2:$A$500,$L$2,'HR-Input'!$B$2:$B$500,"Cohort 1",'HR-Input'!$C$2:$C$500,"Senior FDE",'HR-Input'!$J$2:$J$500,"<>")=0,"–",SUMIFS('HR-Input'!$J$2:$J$500,'HR-Input'!$A$2:$A$500,$L$2,'HR-Input'!$B$2:$B$500,"Cohort 1",'HR-Input'!$C$2:$C$500,"Senior FDE")) -> – | M23: =IF(COUNT(J23:L23)=0,"–",SUM(J23:L23)) -> –
H24: L2 pending | J24: =IF(COUNTIFS('HR-Input'!$A$2:$A$500,$L$2,'HR-Input'!$B$2:$B$500,"Cohort 1",'HR-Input'!$C$2:$C$500,"Associate FDE",'HR-Input'!$L$2:$L$500,"<>")=0,"–",SUMIFS('HR-Input'!$L$2:$L$500,'HR-Input'!$A$2:$A$500,$L$2,'HR-Input'!$B$2:$B$500,"Cohort 1",'HR-Input'!$C$2:$C$500,"Associate FDE")) -> – | K24: =IF(COUNTIFS('HR-Input'!$A$2:$A$500,$L$2,'HR-Input'!$B$2:$B$500,"Cohort 1",'HR-Input'!$C$2:$C$500,"FDE",'HR-Input'!$L$2:$L$500,"<>")=0,"–",SUMIFS('HR-Input'!$L$2:$L$500,'HR-Input'!$A$2:$A$500,$L$2,'HR-Input'!$B$2:$B$500,"Cohort 1",'HR-Input'!$C$2:$C$500,"FDE")) -> 15 | L24: =IF(COUNTIFS('HR-Input'!$A$2:$A$500,$L$2,'HR-Input'!$B$2:$B$500,"Cohort 1",'HR-Input'!$C$2:$C$500,"Senior FDE",'HR-Input'!$L$2:$L$500,"<>")=0,"–",SUMIFS('HR-Input'!$L$2:$L$500,'HR-Input'!$A$2:$A$500,$L$2,'HR-Input'!$B$2:$B$500,"Cohort 1",'HR-Input'!$C$2:$C$500,"Senior FDE")) -> 1 | M24: =IF(COUNT(J24:L24)=0,"–",SUM(J24:L24)) -> 16
H25: L3 pending | J25: =IF(COUNTIFS('HR-Input'!$A$2:$A$500,$L$2,'HR-Input'!$B$2:$B$500,"Cohort 1",'HR-Input'!$C$2:$C$500,"Associate FDE",'HR-Input'!$N$2:$N$500,"<>")=0,"–",SUMIFS('HR-Input'!$N$2:$N$500,'HR-Input'!$A$2:$A$500,$L$2,'HR-Input'!$B$2:$B$500,"Cohort 1",'HR-Input'!$C$2:$C$500,"Associate FDE")) -> – | K25: =IF(COUNTIFS('HR-Input'!$A$2:$A$500,$L$2,'HR-Input'!$B$2:$B$500,"Cohort 1",'HR-Input'!$C$2:$C$500,"FDE",'HR-Input'!$N$2:$N$500,"<>")=0,"–",SUMIFS('HR-Input'!$N$2:$N$500,'HR-Input'!$A$2:$A$500,$L$2,'HR-Input'!$B$2:$B$500,"Cohort 1",'HR-Input'!$C$2:$C$500,"FDE")) -> – | L25: =IF(COUNTIFS('HR-Input'!$A$2:$A$500,$L$2,'HR-Input'!$B$2:$B$500,"Cohort 1",'HR-Input'!$C$2:$C$500,"Senior FDE",'HR-Input'!$N$2:$N$500,"<>")=0,"–",SUMIFS('HR-Input'!$N$2:$N$500,'HR-Input'!$A$2:$A$500,$L$2,'HR-Input'!$B$2:$B$500,"Cohort 1",'HR-Input'!$C$2:$C$500,"Senior FDE")) -> – | M25: =IF(COUNT(J25:L25)=0,"–",SUM(J25:L25)) -> –
H26: CTO round pending | J26: =IF(COUNTIFS('HR-Input'!$A$2:$A$500,$L$2,'HR-Input'!$B$2:$B$500,"Cohort 1",'HR-Input'!$C$2:$C$500,"Associate FDE",'HR-Input'!$P$2:$P$500,"<>")=0,"–",SUMIFS('HR-Input'!$P$2:$P$500,'HR-Input'!$A$2:$A$500,$L$2,'HR-Input'!$B$2:$B$500,"Cohort 1",'HR-Input'!$C$2:$C$500,"Associate FDE")) -> – | K26: =IF(COUNTIFS('HR-Input'!$A$2:$A$500,$L$2,'HR-Input'!$B$2:$B$500,"Cohort 1",'HR-Input'!$C$2:$C$500,"FDE",'HR-Input'!$P$2:$P$500,"<>")=0,"–",SUMIFS('HR-Input'!$P$2:$P$500,'HR-Input'!$A$2:$A$500,$L$2,'HR-Input'!$B$2:$B$500,"Cohort 1",'HR-Input'!$C$2:$C$500,"FDE")) -> 2 | L26: =IF(COUNTIFS('HR-Input'!$A$2:$A$500,$L$2,'HR-Input'!$B$2:$B$500,"Cohort 1",'HR-Input'!$C$2:$C$500,"Senior FDE",'HR-Input'!$P$2:$P$500,"<>")=0,"–",SUMIFS('HR-Input'!$P$2:$P$500,'HR-Input'!$A$2:$A$500,$L$2,'HR-Input'!$B$2:$B$500,"Cohort 1",'HR-Input'!$C$2:$C$500,"Senior FDE")) -> – | M26: =IF(COUNT(J26:L26)=0,"–",SUM(J26:L26)) -> 2
H27: On hold | J27: =IF(COUNTIFS('HR-Input'!$A$2:$A$500,$L$2,'HR-Input'!$B$2:$B$500,"Cohort 1",'HR-Input'!$C$2:$C$500,"Associate FDE",'HR-Input'!$U$2:$U$500,"<>")=0,"–",SUMIFS('HR-Input'!$U$2:$U$500,'HR-Input'!$A$2:$A$500,$L$2,'HR-Input'!$B$2:$B$500,"Cohort 1",'HR-Input'!$C$2:$C$500,"Associate FDE")) -> – | K27: =IF(COUNTIFS('HR-Input'!$A$2:$A$500,$L$2,'HR-Input'!$B$2:$B$500,"Cohort 1",'HR-Input'!$C$2:$C$500,"FDE",'HR-Input'!$U$2:$U$500,"<>")=0,"–",SUMIFS('HR-Input'!$U$2:$U$500,'HR-Input'!$A$2:$A$500,$L$2,'HR-Input'!$B$2:$B$500,"Cohort 1",'HR-Input'!$C$2:$C$500,"FDE")) -> 4 | L27: =IF(COUNTIFS('HR-Input'!$A$2:$A$500,$L$2,'HR-Input'!$B$2:$B$500,"Cohort 1",'HR-Input'!$C$2:$C$500,"Senior FDE",'HR-Input'!$U$2:$U$500,"<>")=0,"–",SUMIFS('HR-Input'!$U$2:$U$500,'HR-Input'!$A$2:$A$500,$L$2,'HR-Input'!$B$2:$B$500,"Cohort 1",'HR-Input'!$C$2:$C$500,"Senior FDE")) -> – | M27: =IF(COUNT(J27:L27)=0,"–",SUM(J27:L27)) -> 4
H28: Rejected (cuml) | J28: =IF(COUNTIFS('HR-Input'!$A$2:$A$500,$L$2,'HR-Input'!$B$2:$B$500,"Cohort 1",'HR-Input'!$C$2:$C$500,"Associate FDE",'HR-Input'!$V$2:$V$500,"<>")=0,"–",SUMIFS('HR-Input'!$V$2:$V$500,'HR-Input'!$A$2:$A$500,$L$2,'HR-Input'!$B$2:$B$500,"Cohort 1",'HR-Input'!$C$2:$C$500,"Associate FDE")) -> – | K28: =IF(COUNTIFS('HR-Input'!$A$2:$A$500,$L$2,'HR-Input'!$B$2:$B$500,"Cohort 1",'HR-Input'!$C$2:$C$500,"FDE",'HR-Input'!$V$2:$V$500,"<>")=0,"–",SUMIFS('HR-Input'!$V$2:$V$500,'HR-Input'!$A$2:$A$500,$L$2,'HR-Input'!$B$2:$B$500,"Cohort 1",'HR-Input'!$C$2:$C$500,"FDE")) -> 11 | L28: =IF(COUNTIFS('HR-Input'!$A$2:$A$500,$L$2,'HR-Input'!$B$2:$B$500,"Cohort 1",'HR-Input'!$C$2:$C$500,"Senior FDE",'HR-Input'!$V$2:$V$500,"<>")=0,"–",SUMIFS('HR-Input'!$V$2:$V$500,'HR-Input'!$A$2:$A$500,$L$2,'HR-Input'!$B$2:$B$500,"Cohort 1",'HR-Input'!$C$2:$C$500,"Senior FDE")) -> 9 | M28: =IF(COUNT(J28:L28)=0,"–",SUM(J28:L28)) -> 20
H29: Slots needed next week | J29: =IF(COUNTIFS('HR-Input'!$A$2:$A$500,$L$2,'HR-Input'!$B$2:$B$500,"Cohort 1",'HR-Input'!$C$2:$C$500,"Associate FDE",'HR-Input'!$W$2:$W$500,"<>")=0,"–",SUMIFS('HR-Input'!$W$2:$W$500,'HR-Input'!$A$2:$A$500,$L$2,'HR-Input'!$B$2:$B$500,"Cohort 1",'HR-Input'!$C$2:$C$500,"Associate FDE")) -> – | K29: =IF(COUNTIFS('HR-Input'!$A$2:$A$500,$L$2,'HR-Input'!$B$2:$B$500,"Cohort 1",'HR-Input'!$C$2:$C$500,"FDE",'HR-Input'!$W$2:$W$500,"<>")=0,"–",SUMIFS('HR-Input'!$W$2:$W$500,'HR-Input'!$A$2:$A$500,$L$2,'HR-Input'!$B$2:$B$500,"Cohort 1",'HR-Input'!$C$2:$C$500,"FDE")) -> 10 | L29: =IF(COUNTIFS('HR-Input'!$A$2:$A$500,$L$2,'HR-Input'!$B$2:$B$500,"Cohort 1",'HR-Input'!$C$2:$C$500,"Senior FDE",'HR-Input'!$W$2:$W$500,"<>")=0,"–",SUMIFS('HR-Input'!$W$2:$W$500,'HR-Input'!$A$2:$A$500,$L$2,'HR-Input'!$B$2:$B$500,"Cohort 1",'HR-Input'!$C$2:$C$500,"Senior FDE")) -> – | M29: =IF(COUNT(J29:L29)=0,"–",SUM(J29:L29)) -> 10
B32: Cohort 2 recruitment
B33: In pipeline now | D33: In CTO round | F33: Offers accepted (cuml) | H33: Joined (cuml) | J33: Rejected (cuml) | L33: Slots needed next week
B34: =IF(COUNT(M38,M50,M51,M52,M53,M54,M45)=0,"–",SUM(M38,M50,M51,M52,M53,M54,M45)) -> 68 | D34: =M54 -> 4 | F34: =M46 -> 14 | H34: =M47 -> – | J34: =M56 -> – | L34: =M57 -> 50
H36: Stage | J36: Associate FDE | K36: FDE | L36: Senior FDE | M36: Total
H37: Recruitment flow, in order (this is what the chart shows)
H38: Screening pending | J38: =IF(COUNTIFS('HR-Input'!$A$2:$A$500,$L$2,'HR-Input'!$B$2:$B$500,"Cohort 2",'HR-Input'!$C$2:$C$500,"Associate FDE",'HR-Input'!$F$2:$F$500,"<>")=0,"–",SUMIFS('HR-Input'!$F$2:$F$500,'HR-Input'!$A$2:$A$500,$L$2,'HR-Input'!$B$2:$B$500,"Cohort 2",'HR-Input'!$C$2:$C$500,"Associate FDE")) -> – | K38: =IF(COUNTIFS('HR-Input'!$A$2:$A$500,$L$2,'HR-Input'!$B$2:$B$500,"Cohort 2",'HR-Input'!$C$2:$C$500,"FDE",'HR-Input'!$F$2:$F$500,"<>")=0,"–",SUMIFS('HR-Input'!$F$2:$F$500,'HR-Input'!$A$2:$A$500,$L$2,'HR-Input'!$B$2:$B$500,"Cohort 2",'HR-Input'!$C$2:$C$500,"FDE")) -> – | L38: =IF(COUNTIFS('HR-Input'!$A$2:$A$500,$L$2,'HR-Input'!$B$2:$B$500,"Cohort 2",'HR-Input'!$C$2:$C$500,"Senior FDE",'HR-Input'!$F$2:$F$500,"<>")=0,"–",SUMIFS('HR-Input'!$F$2:$F$500,'HR-Input'!$A$2:$A$500,$L$2,'HR-Input'!$B$2:$B$500,"Cohort 2",'HR-Input'!$C$2:$C$500,"Senior FDE")) -> – | M38: =IF(COUNT(J38:L38)=0,"–",SUM(J38:L38)) -> –
H39: Screening cleared (cuml) | J39: =IF(COUNTIFS('HR-Input'!$A$2:$A$500,$L$2,'HR-Input'!$B$2:$B$500,"Cohort 2",'HR-Input'!$C$2:$C$500,"Associate FDE",'HR-Input'!$G$2:$G$500,"<>")=0,"–",SUMIFS('HR-Input'!$G$2:$G$500,'HR-Input'!$A$2:$A$500,$L$2,'HR-Input'!$B$2:$B$500,"Cohort 2",'HR-Input'!$C$2:$C$500,"Associate FDE")) -> – | K39: =IF(COUNTIFS('HR-Input'!$A$2:$A$500,$L$2,'HR-Input'!$B$2:$B$500,"Cohort 2",'HR-Input'!$C$2:$C$500,"FDE",'HR-Input'!$G$2:$G$500,"<>")=0,"–",SUMIFS('HR-Input'!$G$2:$G$500,'HR-Input'!$A$2:$A$500,$L$2,'HR-Input'!$B$2:$B$500,"Cohort 2",'HR-Input'!$C$2:$C$500,"FDE")) -> – | L39: =IF(COUNTIFS('HR-Input'!$A$2:$A$500,$L$2,'HR-Input'!$B$2:$B$500,"Cohort 2",'HR-Input'!$C$2:$C$500,"Senior FDE",'HR-Input'!$G$2:$G$500,"<>")=0,"–",SUMIFS('HR-Input'!$G$2:$G$500,'HR-Input'!$A$2:$A$500,$L$2,'HR-Input'!$B$2:$B$500,"Cohort 2",'HR-Input'!$C$2:$C$500,"Senior FDE")) -> – | M39: =IF(COUNT(J39:L39)=0,"–",SUM(J39:L39)) -> –
H40: L1 cleared (cuml) | J40: =IF(COUNTIFS('HR-Input'!$A$2:$A$500,$L$2,'HR-Input'!$B$2:$B$500,"Cohort 2",'HR-Input'!$C$2:$C$500,"Associate FDE",'HR-Input'!$I$2:$I$500,"<>")=0,"–",SUMIFS('HR-Input'!$I$2:$I$500,'HR-Input'!$A$2:$A$500,$L$2,'HR-Input'!$B$2:$B$500,"Cohort 2",'HR-Input'!$C$2:$C$500,"Associate FDE")) -> – | K40: =IF(COUNTIFS('HR-Input'!$A$2:$A$500,$L$2,'HR-Input'!$B$2:$B$500,"Cohort 2",'HR-Input'!$C$2:$C$500,"FDE",'HR-Input'!$I$2:$I$500,"<>")=0,"–",SUMIFS('HR-Input'!$I$2:$I$500,'HR-Input'!$A$2:$A$500,$L$2,'HR-Input'!$B$2:$B$500,"Cohort 2",'HR-Input'!$C$2:$C$500,"FDE")) -> – | L40: =IF(COUNTIFS('HR-Input'!$A$2:$A$500,$L$2,'HR-Input'!$B$2:$B$500,"Cohort 2",'HR-Input'!$C$2:$C$500,"Senior FDE",'HR-Input'!$I$2:$I$500,"<>")=0,"–",SUMIFS('HR-Input'!$I$2:$I$500,'HR-Input'!$A$2:$A$500,$L$2,'HR-Input'!$B$2:$B$500,"Cohort 2",'HR-Input'!$C$2:$C$500,"Senior FDE")) -> – | M40: =IF(COUNT(J40:L40)=0,"–",SUM(J40:L40)) -> –
H41: Berribot assessment cleared (cuml) | J41: =IF(COUNTIFS('HR-Input'!$A$2:$A$500,$L$2,'HR-Input'!$B$2:$B$500,"Cohort 2",'HR-Input'!$C$2:$C$500,"Associate FDE",'HR-Input'!$K$2:$K$500,"<>")=0,"–",SUMIFS('HR-Input'!$K$2:$K$500,'HR-Input'!$A$2:$A$500,$L$2,'HR-Input'!$B$2:$B$500,"Cohort 2",'HR-Input'!$C$2:$C$500,"Associate FDE")) -> – | K41: =IF(COUNTIFS('HR-Input'!$A$2:$A$500,$L$2,'HR-Input'!$B$2:$B$500,"Cohort 2",'HR-Input'!$C$2:$C$500,"FDE",'HR-Input'!$K$2:$K$500,"<>")=0,"–",SUMIFS('HR-Input'!$K$2:$K$500,'HR-Input'!$A$2:$A$500,$L$2,'HR-Input'!$B$2:$B$500,"Cohort 2",'HR-Input'!$C$2:$C$500,"FDE")) -> – | L41: =IF(COUNTIFS('HR-Input'!$A$2:$A$500,$L$2,'HR-Input'!$B$2:$B$500,"Cohort 2",'HR-Input'!$C$2:$C$500,"Senior FDE",'HR-Input'!$K$2:$K$500,"<>")=0,"–",SUMIFS('HR-Input'!$K$2:$K$500,'HR-Input'!$A$2:$A$500,$L$2,'HR-Input'!$B$2:$B$500,"Cohort 2",'HR-Input'!$C$2:$C$500,"Senior FDE")) -> – | M41: =IF(COUNT(J41:L41)=0,"–",SUM(J41:L41)) -> –
H42: L2 cleared (cuml) | J42: =IF(COUNTIFS('HR-Input'!$A$2:$A$500,$L$2,'HR-Input'!$B$2:$B$500,"Cohort 2",'HR-Input'!$C$2:$C$500,"Associate FDE",'HR-Input'!$M$2:$M$500,"<>")=0,"–",SUMIFS('HR-Input'!$M$2:$M$500,'HR-Input'!$A$2:$A$500,$L$2,'HR-Input'!$B$2:$B$500,"Cohort 2",'HR-Input'!$C$2:$C$500,"Associate FDE")) -> – | K42: =IF(COUNTIFS('HR-Input'!$A$2:$A$500,$L$2,'HR-Input'!$B$2:$B$500,"Cohort 2",'HR-Input'!$C$2:$C$500,"FDE",'HR-Input'!$M$2:$M$500,"<>")=0,"–",SUMIFS('HR-Input'!$M$2:$M$500,'HR-Input'!$A$2:$A$500,$L$2,'HR-Input'!$B$2:$B$500,"Cohort 2",'HR-Input'!$C$2:$C$500,"FDE")) -> – | L42: =IF(COUNTIFS('HR-Input'!$A$2:$A$500,$L$2,'HR-Input'!$B$2:$B$500,"Cohort 2",'HR-Input'!$C$2:$C$500,"Senior FDE",'HR-Input'!$M$2:$M$500,"<>")=0,"–",SUMIFS('HR-Input'!$M$2:$M$500,'HR-Input'!$A$2:$A$500,$L$2,'HR-Input'!$B$2:$B$500,"Cohort 2",'HR-Input'!$C$2:$C$500,"Senior FDE")) -> – | M42: =IF(COUNT(J42:L42)=0,"–",SUM(J42:L42)) -> –
H43: L3 cleared (cuml) | J43: =IF(COUNTIFS('HR-Input'!$A$2:$A$500,$L$2,'HR-Input'!$B$2:$B$500,"Cohort 2",'HR-Input'!$C$2:$C$500,"Associate FDE",'HR-Input'!$O$2:$O$500,"<>")=0,"–",SUMIFS('HR-Input'!$O$2:$O$500,'HR-Input'!$A$2:$A$500,$L$2,'HR-Input'!$B$2:$B$500,"Cohort 2",'HR-Input'!$C$2:$C$500,"Associate FDE")) -> – | K43: =IF(COUNTIFS('HR-Input'!$A$2:$A$500,$L$2,'HR-Input'!$B$2:$B$500,"Cohort 2",'HR-Input'!$C$2:$C$500,"FDE",'HR-Input'!$O$2:$O$500,"<>")=0,"–",SUMIFS('HR-Input'!$O$2:$O$500,'HR-Input'!$A$2:$A$500,$L$2,'HR-Input'!$B$2:$B$500,"Cohort 2",'HR-Input'!$C$2:$C$500,"FDE")) -> – | L43: =IF(COUNTIFS('HR-Input'!$A$2:$A$500,$L$2,'HR-Input'!$B$2:$B$500,"Cohort 2",'HR-Input'!$C$2:$C$500,"Senior FDE",'HR-Input'!$O$2:$O$500,"<>")=0,"–",SUMIFS('HR-Input'!$O$2:$O$500,'HR-Input'!$A$2:$A$500,$L$2,'HR-Input'!$B$2:$B$500,"Cohort 2",'HR-Input'!$C$2:$C$500,"Senior FDE")) -> – | M43: =IF(COUNT(J43:L43)=0,"–",SUM(J43:L43)) -> –
H44: CTO round cleared (cuml) | J44: =IF(COUNTIFS('HR-Input'!$A$2:$A$500,$L$2,'HR-Input'!$B$2:$B$500,"Cohort 2",'HR-Input'!$C$2:$C$500,"Associate FDE",'HR-Input'!$Q$2:$Q$500,"<>")=0,"–",SUMIFS('HR-Input'!$Q$2:$Q$500,'HR-Input'!$A$2:$A$500,$L$2,'HR-Input'!$B$2:$B$500,"Cohort 2",'HR-Input'!$C$2:$C$500,"Associate FDE")) -> – | K44: =IF(COUNTIFS('HR-Input'!$A$2:$A$500,$L$2,'HR-Input'!$B$2:$B$500,"Cohort 2",'HR-Input'!$C$2:$C$500,"FDE",'HR-Input'!$Q$2:$Q$500,"<>")=0,"–",SUMIFS('HR-Input'!$Q$2:$Q$500,'HR-Input'!$A$2:$A$500,$L$2,'HR-Input'!$B$2:$B$500,"Cohort 2",'HR-Input'!$C$2:$C$500,"FDE")) -> – | L44: =IF(COUNTIFS('HR-Input'!$A$2:$A$500,$L$2,'HR-Input'!$B$2:$B$500,"Cohort 2",'HR-Input'!$C$2:$C$500,"Senior FDE",'HR-Input'!$Q$2:$Q$500,"<>")=0,"–",SUMIFS('HR-Input'!$Q$2:$Q$500,'HR-Input'!$A$2:$A$500,$L$2,'HR-Input'!$B$2:$B$500,"Cohort 2",'HR-Input'!$C$2:$C$500,"Senior FDE")) -> – | M44: =IF(COUNT(J44:L44)=0,"–",SUM(J44:L44)) -> –
...

Sheet HR-Input
A1: Week_ending | B1: Cohort | C1: Role | D1: Source | E1: Applications_total (cuml) | F1: Screening_pending | G1: Screening_cleared (cuml) | H1: L1_pending | I1: L1_cleared (cuml) | J1: Berribot_applied | K1: Berribot_cleared (cuml) | L1: L2_pending | M1: L2_cleared (cuml) | N1: L3_pending | O1: L3_cleared (cuml) | P1: CTO_pending | Q1: CTO_cleared (cuml) | R1: Offer_extended (pending) | S1: Offer_accepted (cuml) | T1: Joined (cuml) | U1: On_hold | V1: Rejected (cuml) | W1: Slots_needed_next_week | X1: Notes
A2: 46290 | B2: Cohort 2 | C2: Associate FDE | L2: 59 | N2: 5 | P2: 4 | S2: 14 | W2: 50 | X2: 14 offers accepted (incl. 2 UK). L2 to be scheduled 59 (5 diversity). L3 to be scheduled 5 (1 diversity) - need min 50 slots next week. CTO final round scheduled 4 (2 on 9/26, 2 on 9/28). 20 additional diversity candidates scheduled for Berribot for the weekend.
A3: 46290 | B3: Cohort 1 | C3: FDE | D3: External | L3: 15 | P3: 2 | S3: 3 | U3: 4 | V3: 11 | W3: 10 | X3: Email heading is 'FDE/Senior FDE (External)'; entered here as FDE (3 final selects are FDE) - confirm split. L2_pending 15 = 13 in TA screening for L2 scheduling (need min 10 more slots) + 2 interviews scheduled next week. CTO_pending 2 = Lalita Gajbe (9/26) + Sunil Kumar (L3 select, one more short discussion before CTO). 3 offers accepted (Suyosha, Shri, Shreya). 4 on hold after Rubric 2. 11 interview rejects.
A4: 46290 | B4: Cohort 1 | C4: Senior FDE | D4: Internal | E4: 16 | F4: 6 | L4: 1 | V4: 9 | X4: 16 applications: 6 self-assessment assigned, not heard back; 1 L2 to be scheduled; rejected 9 = 7 not shortlisted post self-assessment + 2 L2 interview rejects (Yash Thakkar, Prasann G).

Sheet Dashboard - Training
B1: Academy Training - Weekly Scores Dashboard
B2: All numbers come from the Input - Trainers sheet and update as weeks are filled in. A '–' means not reported yet.
B4: Latest week reported | D4: Overall week average | F4: Hands-on assignments | H4: Proctored assessment | J4: Active students | L4: Overall change vs previous week
B5: =IF($F$43=0,"–","Week "&INDEX('Input - Trainers'!$A:$A,$F$43)) -> Week 6 | D5: =IF($F$43=0,"–",INDEX('Input - Trainers'!$D:$D,$F$43)) -> 0.96 | F5: =IF(OR($F$43=0,INDEX('Input - Trainers'!$B:$B,$F$43)=""),"–",INDEX('Input - Trainers'!$B:$B,$F$43)) -> 0.95 | H5: =IF(OR($F$43=0,INDEX('Input - Trainers'!$C:$C,$F$43)=""),"–",INDEX('Input - Trainers'!$C:$C,$F$43)) -> 0.97 | J5: =IF($F$46=0,"–",INDEX('Input - Trainers'!$E:$E,$F$46)) -> 20 | L5: =IF(OR($F$43=0,$F$44=0),"–",(INDEX('Input - Trainers'!$D:$D,$F$43)-INDEX('Input - Trainers'!$D:$D,$F$44))*100) -> –
B7: Average overall (all weeks) | D7: Best week (overall) | F7: Lowest week (overall) | H7: Weeks reported | J7: Students vs first week
B8: =IF(COUNT('Input - Trainers'!$D$2:$D$500)=0,"–",AVERAGE('Input - Trainers'!$D$2:$D$500)) -> 0.96 | D8: =IF(COUNT('Input - Trainers'!$D$2:$D$500)=0,"–","Week "&INDEX('Input - Trainers'!$A$2:$A$500,MATCH(MAX('Input - Trainers'!$D$2:$D$500),'Input - Trainers'!$D$2:$D$500,0))&" ("&TEXT(MAX('Input - Trainers'!$D$2:$D$500),"0%")&")") -> Week 6 (96%) | F8: =IF(COUNT('Input - Trainers'!$D$2:$D$500)=0,"–","Week "&INDEX('Input - Trainers'!$A$2:$A$500,MATCH(MIN('Input - Trainers'!$D$2:$D$500),'Input - Trainers'!$D$2:$D$500,0))&" ("&TEXT(MIN('Input - Trainers'!$D$2:$D$500),"0%")&")") -> Week 6 (96%) | H8: =COUNT('Input - Trainers'!$D$2:$D$500) -> 1 | J8: =IF($F$45=0,"–",INDEX('Input - Trainers'!$E:$E,$F$46)-INDEX('Input - Trainers'!$E:$E,$F$45)) -> 0
B28: Notes
B29: How to fill: use the Input - Trainers sheet, one row per week. Weeks 1-12 are listed; add week 13 onwards directly underneath (cards and checks read down to row 500). Blue = typed input. Leave future weeks blank.
B30: Overall week average is typed as reported. The check below flags a week if it differs from the simple average of hands-on and proctored by more than 1 point (week 6: 95% and 97% give 96%, so it matches).
B31: The charts show weeks 1-12. To show more weeks, extend the chart data range or ask for it to be extended. Week 6 was entered from the report page; all other weeks are blank for now.
B33: Data checks
B34: Count | C34: Check
B35: =SUMPRODUCT(('Input - Trainers'!$B$2:$B$500<>"")*('Input - Trainers'!$C$2:$C$500<>"")*('Input - Trainers'!$D$2:$D$500<>"")*(ABS('Input - Trainers'!$D$2:$D$500-('Input - Trainers'!$B$2:$B$500+'Input - Trainers'!$C$2:$C$500)/2)>0.01)) -> 0 | C35: Weeks where Overall differs from the simple average of hands-on and proctored by more than 1 point
B36: =SUMPRODUCT(((('Input - Trainers'!$B$2:$B$500<>"")+('Input - Trainers'!$C$2:$C$500<>"")+('Input - Trainers'!$D$2:$D$500<>""))>0)*('Input - Trainers'!$E$2:$E$500="")) -> 0 | C36: Weeks with a score but no Active students number
B37: =SUMPRODUCT(('Input - Trainers'!$A$2:$A$500<>"")*(COUNTIF('Input - Trainers'!$A$2:$A$500,'Input - Trainers'!$A$2:$A$500)>1)) -> 0 | C37: Duplicate week numbers
B38: =SUMPRODUCT(((('Input - Trainers'!$B$2:$B$500<>"")+('Input - Trainers'!$C$2:$C$500<>""))>0)*('Input - Trainers'!$D$2:$D$500="")) -> 0 | C38: Weeks with hands-on or proctored score but no Overall average (not counted on the dashboard)
B41: Workings (row numbers on the Input - Trainers sheet used by the cards above)
B42: A week counts as reported once its Overall average is filled in.
B43: Latest reported week - row on Input - Trainers | F43: =IFERROR(LOOKUP(2,1/('Input - Trainers'!$D$2:$D$500<>""),ROW('Input - Trainers'!$D$2:$D$500)),0) -> 7
B44: Previous reported week - row on Input - Trainers | F44: =IFERROR(LOOKUP(2,1/(('Input - Trainers'!$D$2:$D$500<>"")*(ROW('Input - Trainers'!$D$2:$D$500)<F43)),ROW('Input - Trainers'!$D$2:$D$500)),0) -> 0
B45: First week with Active students - row | F45: =IFERROR(MATCH(1,INDEX(--('Input - Trainers'!$E$2:$E$500<>""),0),0)+1,0) -> 7
B46: Latest week with Active students - row | F46: =IFERROR(LOOKUP(2,1/('Input - Trainers'!$E$2:$E$500<>""),ROW('Input - Trainers'!$E$2:$E$500)),0) -> 7

Sheet Input - Trainers
A1: Week | B1: Hands-on assignments avg (%) | C1: Proctored assessment avg (%) | D1: Overall week average (%) | E1: Active students | F1: Topic / notes
A2: 1
A3: 2
A4: 3
A5: 4
A6: 5
A7: 6 | B7: 0.95 | C7: 0.97 | D7: 0.96 | E7: 20 | F7: Retrieval-Augmented Generation & Enterprise Data Fluency
A8: 7
A9: 8
A10: 9
A11: 10
A12: 11
A13: 12

Sheet Deployment Dashboard
B1: Momentuum Blue - Master Roster Dashboard
B2: Source: Master-Input sheet (transcribed from screenshot). Updates automatically when Master-Input changes. | K2: As of: | L2: =Calc!$H$3 -> 46302
B4: Total headcount (all stages) | D4: Joined till date | F4: Yet to join | H4: Active at client | J4: On bench (joined, unassigned) | L4: Utilization (active / joined FDEs)
B5: =COUNTA('Master-Input'!$A$2:$A$500) -> 38 | D5: =COUNTIFS('Master-Input'!$D$2:$D$500,"<="&Calc!$H$3,'Master-Input'!$A$2:$A$500,"<>") -> 32 | F5: =COUNTIFS('Master-Input'!$D$2:$D$500,">"&Calc!$H$3,'Master-Input'!$A$2:$A$500,"<>") -> 6 | H5: =Calc!B20 -> 10 | J5: =Calc!B23 -> 2 | L5: =IFERROR(Calc!B20/COUNTIFS('Master-Input'!$D$2:$D$500,"<="&Calc!$H$3,'Master-Input'!$C$2:$C$500,"<>Trainee",'Master-Input'!$A$2:$A$500,"<>"),0) -> 0.83333333
B7: Monthly revenue run-rate (USD) | D7: Annualised run-rate (USD) | F7: Avg billing rate (USD/hr) | H7: Client starting soon | J7: Contracts ending soon | L7: Data checks flagged
B8: =Calc!C36 -> 144000 | D8: =Calc!C36*12 -> 1728000 | F8: =Calc!D36 -> 90 | H8: =Calc!B21 -> 0 | J8: =SUMPRODUCT(('Master-Input'!$F$2:$F$500<>"")*('Master-Input'!$G$2:$G$500<=Calc!$H$3)*('Master-Input'!$H$2:$H$500>=Calc!$H$3)*('Master-Input'!$H$2:$H$500<=Calc!$H$3+Calc!$H$5)) -> 2 | L8: =SUM(B84:B87) -> 1
H43: Client | I43: Active FDEs | J43: Monthly rev (USD) | K43: Avg rate (USD/hr)
H44: =Calc!A29 -> TriNet | I44: =Calc!B29 -> 4 | J44: =Calc!C29 -> 48000 | K44: =Calc!D29 -> 75
H45: =Calc!A30 -> PMI | I45: =Calc!B30 -> 1 | J45: =Calc!C30 -> 16000 | K45: =Calc!D30 -> 100
H46: =Calc!A31 -> Hiscox | I46: =Calc!B31 -> 1 | J46: =Calc!C31 -> 16000 | K46: =Calc!D31 -> 100
H47: =Calc!A32 -> SEI | I47: =Calc!B32 -> 2 | J47: =Calc!C32 -> 32000 | K47: =Calc!D32 -> 100
H48: =Calc!A33 -> M&T Bank | I48: =Calc!B33 -> 1 | J48: =Calc!C33 -> 16000 | K48: =Calc!D33 -> 100
H49: =Calc!A34 -> Peabody | I49: =Calc!B34 -> 1 | J49: =Calc!C34 -> 16000 | K49: =Calc!D34 -> 100
H50: =Calc!A35 -> Other clients | I50: =Calc!B35 -> 0 | J50: =Calc!C35 -> 0 | K50: =Calc!D35 -> 0
H51: =Calc!A36 -> Total active | I51: =Calc!B36 -> 10 | J51: =Calc!C36 -> 144000 | K51: =Calc!D36 -> 90
B58: Availability flow: location > availability > deployment (all FDEs, not just active)
B59: Total FDEs (all stages) | D59: Available now | F59: Available in future | H59: Assigned to a client (incl. starting soon) | J59: On bench | L59: Monthly revenue incl. starting soon (USD)
B60: =Calc!D56 -> 38 | D60: =Calc!B56 -> 12 | F60: =Calc!C56 -> 26 | H60: =Calc!B56-Calc!B66 -> 10 | J60: =Calc!B66 -> 2 | L60: =Calc!C69 -> 144000
B80: Available now = has a client assigned (including starting soon) or has started with no client and is not a Trainee. Available in future = Trainees and people who have not started yet. Revenue = rate x hours x weeks/month. Source: Master-Input sheet via Calc rows 48-70.
B82: Data quality checks
B83: Count | C83: Check
B84: =SUMPRODUCT(('Master-Input'!$F$2:$F$500<>"")*('Master-Input'!$G$2:$G$500<'Master-Input'!$D$2:$D$500)) -> 1 | C84: Client start date is earlier than the person's Momentuum Blue start date
B85: =SUMPRODUCT(('Master-Input'!$A$2:$A$500<>"")*(COUNTIF('Master-Input'!$A$2:$A$500,'Master-Input'!$A$2:$A$500)>1)) -> 0 | C85: Duplicate FDE names
B86: =SUMPRODUCT(('Master-Input'!$F$2:$F$500<>"")*(('Master-Input'!$I$2:$I$500=0)+('Master-Input'!$J$2:$J$500=0)>0)) -> 0 | C86: Client assigned but billing rate or hours missing
B87: =ABS(COUNTA('Master-Input'!$A$2:$A$500)-SUM(Calc!B20:B25))+ABS(COUNTA('Master-Input'!$A$2:$A$500)-SUM(Calc!D4:D6)) -> 0 | C87: Status or career-stage buckets do not add up to headcount (unexpected stage / dates)
B89: Revenue = billing rate x hours/week x billing weeks per month (Calc!H4), counted only for contracts active on the as-of date.

Sheet Master-Input
A1: FDE | B1: Location | C1: Career_Stage | D1: Start_date_with_Momentuum_blue | E1: Source | F1: Current_Client | G1: Start_date_with_Current_Client | H1: End_date_with_Current_Client | I1: USD_Equivalent_Billing_Rate (USD/hour) | J1: Hours/week | K1: Monthly_Revenue
A2: Atul Moglewar | B2: India | C2: Senior FDE | D2: 46204 | E2: Internal | F2: TriNet | G2: 46218 | H2: 46308 | I2: 50 | J2: 40 | K2: =IF(OR(I2="",J2=""),"",I2*J2*Calc!$H$4) -> 8000
A3: Jason Bowers | B3: USA | C3: Senior FDE | D3: 46204 | E3: Internal | F3: PMI | G3: 46237 | H3: 46356 | I3: 100 | J3: 40 | K3: =IF(OR(I3="",J3=""),"",I3*J3*Calc!$H$4) -> 16000
A4: Gavin Dias | B4: USA | C4: Senior FDE | D4: 46265 | E4: Internal | F4: Hiscox | G4: 46265 | H4: 46387 | I4: 100 | J4: 40 | K4: =IF(OR(I4="",J4=""),"",I4*J4*Calc!$H$4) -> 16000
A5: Sahil Shah | B5: USA | C5: Senior FDE | D5: 46235 | E5: Internal | F5: SEI | G5: 46204 | H5: 46446 | I5: 100 | J5: 40 | K5: =IF(OR(I5="",J5=""),"",I5*J5*Calc!$H$4) -> 16000
A6: Rinkesh Chauhan | B6: USA | C6: Senior FDE | D6: 46266 | E6: Internal | F6: M&T Bank | G6: 46279 | H6: 46419 | I6: 100 | J6: 40 | K6: =IF(OR(I6="",J6=""),"",I6*J6*Calc!$H$4) -> 16000
A7: Aditya Chouhan | B7: India | C7: Senior FDE | D7: 46266 | E7: Internal | F7: SEI | G7: 46266 | H7: 46446 | I7: 100 | J7: 40 | K7: =IF(OR(I7="",J7=""),"",I7*J7*Calc!$H$4) -> 16000
A8: Anand Patil | B8: UK | C8: Senior FDE | D8: 46266 | E8: Internal | F8: Peabody | G8: 46269 | H8: 46477 | I8: 100 | J8: 40 | K8: =IF(OR(I8="",J8=""),"",I8*J8*Calc!$H$4) -> 16000
A9: Gustavo Romero | B9: LATAM | C9: Senior FDE | D9: 46293 | E9: Internal | F9: TriNet | G9: 46293 | H9: 46477 | I9: 100 | J9: 40 | K9: =IF(OR(I9="",J9=""),"",I9*J9*Calc!$H$4) -> 16000
A10: Jay Patel | B10: USA | C10: Senior FDE | D10: 46293 | E10: Internal | F10: TriNet | G10: 46293 | H10: 46477 | I10: 75 | J10: 40 | K10: =IF(OR(I10="",J10=""),"",I10*J10*Calc!$H$4) -> 12000
A11: Suyosha Acharya | B11: USA | C11: FDE | D11: 46300 | E11: External | F11: TriNet | G11: 46300 | H11: 46477 | I11: 75 | J11: 40 | K11: =IF(OR(I11="",J11=""),"",I11*J11*Calc!$H$4) -> 12000
A12: Shreya Jamsandekar | B12: USA | C12: FDE | D12: 46307 | E12: External | K12: =IF(OR(I12="",J12=""),"",I12*J12*Calc!$H$4)
A13: Shri Aiswarya Gorle | B13: USA | C13: FDE | D13: 46300 | E13: External | K13: =IF(OR(I13="",J13=""),"",I13*J13*Calc!$H$4)
A14: Jorge Hernandez | B14: LATAM | C14: Senior FDE | D14: 46235 | E14: Internal | K14: =IF(OR(I14="",J14=""),"",I14*J14*Calc!$H$4)
A15: Ana Robles | B15: LATAM | C15: Senior FDE | D15: 46326 | E15: Internal | K15: =IF(OR(I15="",J15=""),"",I15*J15*Calc!$H$4)
A16: Tanul Thanvi | B16: UK | C16: Senior FDE | D16: 46389 | E16: Internal | K16: =IF(OR(I16="",J16=""),"",I16*J16*Calc!$H$4)
A17: Rashmikant Gadia | B17: UK | C17: Senior FDE | D17: 46326 | E17: Internal | K17: =IF(OR(I17="",J17=""),"",I17*J17*Calc!$H$4)
A18: Ram Shankar Gupta | B18: Canada | C18: Senior FDE | D18: 46326 | E18: Internal | K18: =IF(OR(I18="",J18=""),"",I18*J18*Calc!$H$4)
A19: Avinash Mishra | B19: Canada | C19: Senior FDE | D19: 46389 | E19: Internal | K19: =IF(OR(I19="",J19=""),"",I19*J19*Calc!$H$4)
A20: Yash Deshmukh | B20: USA | C20: Trainee | D20: 46251 | E20: External | K20: =IF(OR(I20="",J20=""),"",I20*J20*Calc!$H$4)
A21: Atharv Raotole | B21: USA | C21: Trainee | D21: 46251 | E21: External | K21: =IF(OR(I21="",J21=""),"",I21*J21*Calc!$H$4)
A22: Atharva Chundurwar | B22: USA | C22: Trainee | D22: 46251 | E22: External | K22: =IF(OR(I22="",J22=""),"",I22*J22*Calc!$H$4)
A23: Caleb Rhys Hollander | B23: USA | C23: Trainee | D23: 46251 | E23: External | K23: =IF(OR(I23="",J23=""),"",I23*J23*Calc!$H$4)
... A39: Zhanping Zeng | B39: USA | C39: Trainee | D39: 46251 | E39: External | K39: =IF(OR(I39="",J39=""),"",I39*J39*Calc!$H$4)
K40: =IF(OR(I40="",J40=""),"",I40*J40*Calc!$H$4)
K41: =IF(OR(I41="",J41=""),"",I41*J41*Calc!$H$4)
K42: =IF(OR(I42="",J42=""),"",I42*J42*Calc!$H$4)
K43: =IF(OR(I43="",J43=""),"",I43*J43*Calc!$H$4)
K44: =IF(OR(I44="",J44=""),"",I44*J44*Calc!$H$4)
K45: =IF(OR(I45="",J45=""),"",I45*J45*Calc!$H$4)
K46: =IF(OR(I46="",J46=""),"",I46*J46*Calc!$H$4)
K47: =IF(OR(I47="",J47=""),"",I47*J47*Calc!$H$4)
K48: =IF(OR(I48="",J48=""),"",I48*J48*Calc!$H$4)
K49: =IF(OR(I49="",J49=""),"",I49*J49*Calc!$H$4)
K50: =IF(OR(I50="",J50=""),"",I50*J50*Calc!$H$4)
K51: =IF(OR(I51="",J51=""),"",I51*J51*Calc!$H$4)
... K200: =IF(OR(I200="",J200=""),"",I200*J200*Calc!$H$4)

Sheet Calc
A1: CALC - settings, notes and chart feeds (everything visible: edit blue/yellow cells only)
G2: SETTINGS (shared by all dashboards)
A3: Career stage | B3: Internal | C3: External | D3: Total | E3: Source: Master-Input!C (Career_Stage) x Master-Input!E (Source) | G3: As-of date | H3: =TODAY() -> 46302 | I3: Live date. Overwrite with a fixed date to view a past snapshot.
A4: Senior FDE | B4: =COUNTIFS('Master-Input'!$C$2:$C$500,$A4,'Master-Input'!$E$2:$E$500,"Internal") -> 15 | C4: =COUNTIFS('Master-Input'!$C$2:$C$500,$A4,'Master-Input'!$E$2:$E$500,"External") -> 0 | D4: =COUNTIF('Master-Input'!$C$2:$C$500,$A4) -> 15 | G4: Billing weeks per month | H4: 4 | I4: ASSUMPTION - matches Monthly_Revenue in the source sheet (rate x hours x 4).
A5: FDE | B5: =COUNTIFS('Master-Input'!$C$2:$C$500,$A5,'Master-Input'!$E$2:$E$500,"Internal") -> 0 | C5: =COUNTIFS('Master-Input'!$C$2:$C$500,$A5,'Master-Input'!$E$2:$E$500,"External") -> 3 | D5: =COUNTIF('Master-Input'!$C$2:$C$500,$A5) -> 3 | G5: 'Ending soon' window (days) | H5: 60 | I5: Contracts ending within this many days are flagged.
A6: Trainee | B6: =COUNTIFS('Master-Input'!$C$2:$C$500,$A6,'Master-Input'!$E$2:$E$500,"Internal") -> 0 | C6: =COUNTIFS('Master-Input'!$C$2:$C$500,$A6,'Master-Input'!$E$2:$E$500,"External") -> 20 | D6: =COUNTIF('Master-Input'!$C$2:$C$500,$A6) -> 20
G8: READ ME
G9: Layout: Deployment Dashboard (dashboard) | Master-Input (data) | Calc (this sheet). A new data sheet gets its own dashboard sheet; its calculation blocks are added on this Calc sheet below the existing ones.
A10: Location | B10: Headcount | E10: Source: Master-Input!B (Location) | G10: Blue text = typed input. Black = formula (do not overwrite). Yellow = assumption you can change.
A11: USA | B11: =COUNTIF('Master-Input'!$B$2:$B$500,A11) -> 28 | G11: Column E beside each table below states exactly which Master-Input columns feed it.
A12: India | B12: =COUNTIF('Master-Input'!$B$2:$B$500,A12) -> 2 | G12: Add new people at the bottom of Master-Input (Monthly_Revenue is pre-filled to row 200). Dashboards read down to row 500.
A13: UK | B13: =COUNTIF('Master-Input'!$B$2:$B$500,A13) -> 3 | G13: Typed label lists (locations, clients, months) must be extended when a new one appears. 'Other' rows catch anything missed.
A14: LATAM | B14: =COUNTIF('Master-Input'!$B$2:$B$500,A14) -> 3 | G14: TRANSCRIPTION NOTES (from a screenshot)
A15: Canada | B15: =COUNTIF('Master-Input'!$B$2:$B$500,A15) -> 2 | G15: - Names cut off on screen are entered as visible: 'Caleb Rhys Hollande', 'Manikandan Sundar', 'Smit Mahesh Pancha'. Please complete them.
A16: Other | B16: =COUNTA('Master-Input'!$A$2:$A$500)-SUM(B11:B15) -> 0 | G16: - Monthly_Revenue recalculated as rate x hours x 4; matches every value on the screenshot.
G17: - Check: Sahil Shah's client start (01-07-2026) is before his Momentuum Blue start (01-08-2026); Gustavo and Jay now end 31-03-2027 (earlier tracker said 31-12-2026).
A19: Where is everyone today | B19: People | E19: Source: Master-Input!A,C,D,F,G,H (names, stage, start dates, client, client dates) vs As-of date
A20: Active at client | B20: =SUMPRODUCT(('Master-Input'!$F$2:$F$500<>"")*('Master-Input'!$G$2:$G$500<=Calc!$H$3)*('Master-Input'!$H$2:$H$500>=Calc!$H$3)) -> 10
A21: Client starting soon | B21: =SUMPRODUCT(('Master-Input'!$F$2:$F$500<>"")*('Master-Input'!$G$2:$G$500>Calc!$H$3)) -> 0
A22: Client contract ended | B22: =SUMPRODUCT(('Master-Input'!$F$2:$F$500<>"")*('Master-Input'!$H$2:$H$500<Calc!$H$3)) -> 0
A23: On bench (joined, unassigned) | B23: =SUMPRODUCT(('Master-Input'!$A$2:$A$500<>"")*('Master-Input'!$F$2:$F$500="")*('Master-Input'!$D$2:$D$500<=Calc!$H$3)*('Master-Input'!$C$2:$C$500<>"Trainee")) -> 2
A24: In training (Trainees) | B24: =SUMPRODUCT(('Master-Input'!$A$2:$A$500<>"")*('Master-Input'!$F$2:$F$500="")*('Master-Input'!$C$2:$C$500="Trainee")) -> 20
A25: Yet to join | B25: =SUMPRODUCT(('Master-Input'!$A$2:$A$500<>"")*('Master-Input'!$F$2:$F$500="")*('Master-Input'!$D$2:$D$500>Calc!$H$3)*('Master-Input'!$C$2:$C$500<>"Trainee")) -> 6
A28: Client (active only) | B28: Active FDEs | C28: Monthly revenue (USD) | D28: Avg rate (USD/hr) | E28: Source: Master-Input!F,G,H,I,J (client, client dates, rate, hours) x weeks/month (H4)
A29: TriNet | B29: =SUMPRODUCT(('Master-Input'!$F$2:$F$500=$A29)*('Master-Input'!$G$2:$G$500<=Calc!$H$3)*('Master-Input'!$H$2:$H$500>=Calc!$H$3)) -> 4 | C29: =SUMPRODUCT(('Master-Input'!$F$2:$F$500=$A29)*('Master-Input'!$G$2:$G$500<=Calc!$H$3)*('Master-Input'!$H$2:$H$500>=Calc!$H$3)*'Master-Input'!$I$2:$I$500*'Master-Input'!$J$2:$J$500*Calc!$H$4) -> 48000 | D29: =IF(B29=0,0,SUMPRODUCT(('Master-Input'!$F$2:$F$500=$A29)*('Master-Input'!$G$2:$G$500<=Calc!$H$3)*('Master-Input'!$H$2:$H$500>=Calc!$H$3)*'Master-Input'!$I$2:$I$500)/B29) -> 75
A30: PMI | B30: =SUMPRODUCT(('Master-Input'!$F$2:$F$500=$A30)*('Master-Input'!$G$2:$G$500<=Calc!$H$3)*('Master-Input'!$H$2:$H$500>=Calc!$H$3)) -> 1 | C30: =SUMPRODUCT(('Master-Input'!$F$2:$F$500=$A30)*('Master-Input'!$G$2:$G$500<=Calc!$H$3)*('Master-Input'!$H$2:$H$500>=Calc!$H$3)*'Master-Input'!$I$2:$I$500*'Master-Input'!$J$2:$J$500*Calc!$H$4) -> 16000 | D30: =IF(B30=0,0,SUMPRODUCT(('Master-Input'!$F$2:$F$500=$A30)*('Master-Input'!$G$2:$G$500<=Calc!$H$3)*('Master-Input'!$H$2:$H$500>=Calc!$H$3)*'Master-Input'!$I$2:$I$500)/B30) -> 100
A31: Hiscox | B31: =SUMPRODUCT(('Master-Input'!$F$2:$F$500=$A31)*('Master-Input'!$G$2:$G$500<=Calc!$H$3)*('Master-Input'!$H$2:$H$500>=Calc!$H$3)) -> 1 | C31: =SUMPRODUCT(('Master-Input'!$F$2:$F$500=$A31)*('Master-Input'!$G$2:$G$500<=Calc!$H$3)*('Master-Input'!$H$2:$H$500>=Calc!$H$3)*'Master-Input'!$I$2:$I$500*'Master-Input'!$J$2:$J$500*Calc!$H$4) -> 16000 | D31: =IF(B31=0,0,SUMPRODUCT(('Master-Input'!$F$2:$F$500=$A31)*('Master-Input'!$G$2:$G$500<=Calc!$H$3)*('Master-Input'!$H$2:$H$500>=Calc!$H$3)*'Master-Input'!$I$2:$I$500)/B31) -> 100
A32: SEI | B32: =SUMPRODUCT(('Master-Input'!$F$2:$F$500=$A32)*('Master-Input'!$G$2:$G$500<=Calc!$H$3)*('Master-Input'!$H$2:$H$500>=Calc!$H$3)) -> 2 | C32: =SUMPRODUCT(('Master-Input'!$F$2:$F$500=$A32)*('Master-Input'!$G$2:$G$500<=Calc!$H$3)*('Master-Input'!$H$2:$H$500>=Calc!$H$3)*'Master-Input'!$I$2:$I$500*'Master-Input'!$J$2:$J$500*Calc!$H$4) -> 32000 | D32: =IF(B32=0,0,SUMPRODUCT(('Master-Input'!$F$2:$F$500=$A32)*('Master-Input'!$G$2:$G$500<=Calc!$H$3)*('Master-Input'!$H$2:$H$500>=Calc!$H$3)*'Master-Input'!$I$2:$I$500)/B32) -> 100
A33: M&T Bank | B33: =SUMPRODUCT(('Master-Input'!$F$2:$F$500=$A33)*('Master-Input'!$G$2:$G$500<=Calc!$H$3)*('Master-Input'!$H$2:$H$500>=Calc!$H$3)) -> 1 | C33: =SUMPRODUCT(('Master-Input'!$F$2:$F$500=$A33)*('Master-Input'!$G$2:$G$500<=Calc!$H$3)*('Master-Input'!$H$2:$H$500>=Calc!$H$3)*'Master-Input'!$I$2:$I$500*'Master-Input'!$J$2:$J$500*Calc!$H$4) -> 16000 | D33: =IF(B33=0,0,SUMPRODUCT(('Master-Input'!$F$2:$F$500=$A33)*('Master-Input'!$G$2:$G$500<=Calc!$H$3)*('Master-Input'!$H$2:$H$500>=Calc!$H$3)*'Master-Input'!$I$2:$I$500)/B33) -> 100
